Workbook

Sheet 2026 Summary
A1: Month | B1: Total Invested | C1: Number of Companies | D1: Asset Manager | G1: Blacklist
D2: Danske Bank | E2: Jyske Bank | F2: SEB | G2: UN | H2: AFSC | I2: WhoProfits
A3: 46023 | B3: ='Jan 2026'!M13 -> 0 | C3: =COUNTIF('Jan 2026'!F2:F150,"*") -> 0 | D3: ='Jan 2026'!N8 -> 0 | E3: ='Jan 2026'!N9 -> 0 | F3: ='Jan 2026'!N10 -> 0 | G3: ='Jan 2026'!N3 -> 0 | H3: ='Jan 2026'!N4 -> 0 | I3: ='Jan 2026'!N5 -> 0 | AA3: ='Jan 2026'!F2 -> 0
A4: 46054 | B4: ='Feb 2026'!M13 -> 0 | C4: =COUNTIF('Feb 2026'!F2:F150,"*") -> 0 | D4: ='Feb 2026'!N8 -> 0 | E4: ='Feb 2026'!N9 -> 0 | F4: ='Feb 2026'!N10 -> 0 | G4: ='Feb 2026'!N3 -> 0 | H4: ='Feb 2026'!N4 -> 0 | I4: ='Feb 2026'!N5 -> 0 | AA4: ='Jan 2026'!F3 -> 0
A5: 46082 | B5: ='Mar 2026'!M13 -> 0 | C5: =COUNTIF('Mar 2026'!F2:F150,"*") -> 0 | D5: ='Mar 2026'!N8 -> 0 | E5: ='Mar 2026'!N9 -> 0 | F5: ='Mar 2026'!N10 -> 0 | G5: ='Mar 2026'!N3 -> 0 | H5: ='Mar 2026'!N4 -> 0 | I5: ='Mar 2026'!N5 -> 0 | AA5: ='Jan 2026'!F4 -> 0
A6: 46113 | B6: ='Apr 2026'!M13 -> 0 | C6: =COUNTIF('Apr 2026'!F2:F150,"*") -> 0 | D6: ='Apr 2026'!N8 -> 0 | E6: ='Apr 2026'!N9 -> 0 | F6: ='Apr 2026'!N10 -> 0 | G6: ='Apr 2026'!N3 -> 0 | H6: ='Apr 2026'!N4 -> 0 | I6: ='Apr 2026'!N5 -> 0 | AA6: ='Jan 2026'!F5 -> 0
A7: 46143 | B7: ='May 2026'!M13 -> 0 | C7: =COUNTIF('May 2026'!F2:F150,"*") -> 0 | D7: ='May 2026'!N8 -> 0 | E7: ='May 2026'!N9 -> 0 | F7: ='May 2026'!N10 -> 0 | G7: ='May 2026'!N3 -> 0 | H7: ='May 2026'!N4 -> 0 | I7: ='May 2026'!N5 -> 0 | AA7: ='Jan 2026'!F6 -> 0
A8: 46174 | B8: ='Jun 2026'!M13 -> 0 | C8: =COUNTIF('Jun 2026'!F2:F150,"*") -> 0 | D8: ='Jun 2026'!N8 -> 0 | E8: ='Jun 2026'!N9 -> 0 | F8: ='Jun 2026'!N10 -> 0 | G8: ='Jun 2026'!N3 -> 0 | H8: ='Jun 2026'!N4 -> 0 | I8: ='Jun 2026'!N5 -> 0 | AA8: ='Jan 2026'!F7 -> 0
A9: 46204 | B9: ='Jul 2026'!M13 -> 0 | C9: =COUNTIF('Jul 2026'!F2:F150,"*") -> 0 | D9: ='Jul 2026'!N8 -> 0 | E9: ='Jul 2026'!N9 -> 0 | F9: ='Jul 2026'!N10 -> 0 | G9: ='Jul 2026'!N3 -> 0 | H9: ='Jul 2026'!N4 -> 0 | I9: ='Jul 2026'!N5 -> 0 | AA9: ='Jan 2026'!F8 -> 0
A10: 46235 | B10: ='Aug 2026'!M13 -> 0 | C10: =COUNTIF('Aug 2026'!F2:F150,"*") -> 0 | D10: ='Aug 2026'!N8 -> 0 | E10: ='Aug 2026'!N9 -> 0 | F10: ='Aug 2026'!N10 -> 0 | G10: ='Aug 2026'!N3 -> 0 | H10: ='Aug 2026'!N4 -> 0 | I10: ='Aug 2026'!N5 -> 0 | AA10: ='Jan 2026'!F9 -> 0
A11: 46266 | B11: ='Sep 2026'!M13 -> 0 | C11: =COUNTIF('Sep 2026'!F2:F150,"*") -> 0 | D11: ='Sep 2026'!N8 -> 0 | E11: ='Sep 2026'!N9 -> 0 | F11: ='Sep 2026'!N10 -> 0 | G11: ='Sep 2026'!N3 -> 0 | H11: ='Sep 2026'!N4 -> 0 | I11: ='Sep 2026'!N5 -> 0 | AA11: ='Jan 2026'!F10 -> 0
A12: 46296 | B12: ='Oct 2026'!M13 -> 0 | C12: =COUNTIF('Oct 2026'!F2:F150,"*") -> 0 | D12: ='Oct 2026'!N8 -> 0 | E12: ='Oct 2026'!N9 -> 0 | F12: ='Oct 2026'!N10 -> 0 | G12: ='Oct 2026'!N3 -> 0 | H12: ='Oct 2026'!N4 -> 0 | I12: ='Oct 2026'!N5 -> 0 | AA12: ='Jan 2026'!F11 -> 0
A13: 46327 | B13: ='Nov 2026'!M13 -> 0 | C13: =COUNTIF('Nov 2026'!F2:F150,"*") -> 0 | D13: ='Nov 2026'!N8 -> 0 | E13: ='Nov 2026'!N9 -> 0 | F13: ='Nov 2026'!N10 -> 0 | G13: ='Nov 2026'!N3 -> 0 | H13: ='Nov 2026'!N4 -> 0 | I13: ='Nov 2026'!N5 -> 0 | AA13: ='Jan 2026'!F12 -> 0
A14: 46357 | B14: ='Dec 2026'!M13 -> 0 | C14: =COUNTIF('Dec 2026'!F2:F150,"*") -> 0 | D14: ='Dec 2026'!N8 -> 0 | E14: ='Dec 2026'!N9 -> 0 | F14: ='Dec 2026'!N10 -> 0 | G14: ='Dec 2026'!N3 -> 0 | H14: ='Dec 2026'!N4 -> 0 | I14: ='Dec 2026'!N5 -> 0 | AA14: ='Jan 2026'!F13 -> 0
A15: Average | B15: =AVERAGE(B3:B14) -> 0 | AA15: ='Jan 2026'!F14 -> 0
A16: Companies | B16: =COUNTIF(A18:A150,"*") -> 0 | AA16: ='Jan 2026'!F15 -> 0
AA17: ='Jan 2026'!F16 -> 0
A18: {=_xlfn._xlws.SORT(_xlfn.UNIQUE(AA:AA))} -> 0 | B18: =A3 -> 46023 | C18: =A4 -> 46054 | D18: =A5 -> 46082 | E18: =A6 -> 46113 | F18: =A7 -> 46143 | G18: =A8 -> 46174 | H18: =A9 -> 46204 | I18: =A10 -> 46235 | J18: =A11 -> 46266 | K18: =A12 -> 46296 | L18: =A13 -> 46327 | M18: =A14 -> 46357 | AA18: ='Jan 2026'!F17 -> 0
A19: 0 | B19: =SUMIF('Jan 2026'!$F$2:$F$150,'2026 Summary'!A19,'Jan 2026'!$G$2:$G$150) -> 0 | C19: =SUMIF('Feb 2026'!$F$2:$F$150,'2026 Summary'!A19,'Feb 2026'!$G$2:$G$150) -> 0 | D19: =SUMIF('Mar 2026'!$F$2:$F$150,'2026 Summary'!A19,'Mar 2026'!$G$2:$G$150) -> 0 | E19: =SUMIF('Apr 2026'!$F$2:$F$150,'2026 Summary'!A19,'Apr 2026'!$G$2:$G$150) -> 0 | F19: =SUMIF('May 2026'!$F$2:$F$150,'2026 Summary'!A19,'May 2026'!$G$2:$G$150) -> 0 | G19: =SUMIF('Jun 2026'!$F$2:$F$150,'2026 Summary'!A19,'Jun 2026'!$G$2:$G$150) -> 0 | H19: =SUMIF('Jul 2026'!$F$2:$F$150,'2026 Summary'!A19,'Jul 2026'!$G$2:$G$150) -> 0 | I19: =SUMIF('Aug 2026'!$F$2:$F$150,'2026 Summary'!A19,'Aug 2026'!$G$2:$G$150) -> 0 | J19: =SUMIF('Sep 2026'!$F$2:$F$150,'2026 Summary'!A19,'Sep 2026'!$G$2:$G$150) -> 0 | K19: =SUMIF('Oct 2026'!$F$2:$F$150,'2026 Summary'!A19,'Oct 2026'!$G$2:$G$150) -> 0 | L19: =SUMIF('Nov 2026'!$F$2:$F$150,'2026 Summary'!A19,'Nov 2026'!$G$2:$G$150) -> 0 | M19: =SUMIF('Dec 2026'!$F$2:$F$150,'2026 Summary'!A19,'Dec 2026'!$G$2:$G$150) -> 0 | AA19: ='Jan 2026'!F18 -> 0
B20: =SUMIF('Jan 2026'!$F$2:$F$150,'2026 Summary'!A20,'Jan 2026'!$G$2:$G$150) -> 0 | C20: =SUMIF('Feb 2026'!$F$2:$F$150,'2026 Summary'!A20,'Feb 2026'!$G$2:$G$150) -> 0 | D20: =SUMIF('Mar 2026'!$F$2:$F$150,'2026 Summary'!A20,'Mar 2026'!$G$2:$G$150) -> 0 | E20: =SUMIF('Apr 2026'!$F$2:$F$150,'2026 Summary'!A20,'Apr 2026'!$G$2:$G$150) -> 0 | F20: =SUMIF('May 2026'!$F$2:$F$150,'2026 Summary'!A20,'May 2026'!$G$2:$G$150) -> 0 | G20: =SUMIF('Jun 2026'!$F$2:$F$150,'2026 Summary'!A20,'Jun 2026'!$G$2:$G$150) -> 0 | H20: =SUMIF('Jul 2026'!$F$2:$F$150,'2026 Summary'!A20,'Jul 2026'!$G$2:$G$150) -> 0 | I20: =SUMIF('Aug 2026'!$F$2:$F$150,'2026 Summary'!A20,'Aug 2026'!$G$2:$G$150) -> 0 | J20: =SUMIF('Sep 2026'!$F$2:$F$150,'2026 Summary'!A20,'Sep 2026'!$G$2:$G$150) -> 0 | K20: =SUMIF('Oct 2026'!$F$2:$F$150,'2026 Summary'!A20,'Oct 2026'!$G$2:$G$150) -> 0 | L20: =SUMIF('Nov 2026'!$F$2:$F$150,'2026 Summary'!A20,'Nov 2026'!$G$2:$G$150) -> 0 | M20: =SUMIF('Dec 2026'!$F$2:$F$150,'2026 Summary'!A20,'Dec 2026'!$G$2:$G$150) -> 0 | AA20: ='Jan 2026'!F19 -> 0
B21: =SUMIF('Jan 2026'!$F$2:$F$150,'2026 Summary'!A21,'Jan 2026'!$G$2:$G$150) -> 0 | C21: =SUMIF('Feb 2026'!$F$2:$F$150,'2026 Summary'!A21,'Feb 2026'!$G$2:$G$150) -> 0 | D21: =SUMIF('Mar 2026'!$F$2:$F$150,'2026 Summary'!A21,'Mar 2026'!$G$2:$G$150) -> 0 | E21: =SUMIF('Apr 2026'!$F$2:$F$150,'2026 Summary'!A21,'Apr 2026'!$G$2:$G$150) -> 0 | F21: =SUMIF('May 2026'!$F$2:$F$150,'2026 Summary'!A21,'May 2026'!$G$2:$G$150) -> 0 | G21: =SUMIF('Jun 2026'!$F$2:$F$150,'2026 Summary'!A21,'Jun 2026'!$G$2:$G$150) -> 0 | H21: =SUMIF('Jul 2026'!$F$2:$F$150,'2026 Summary'!A21,'Jul 2026'!$G$2:$G$150) -> 0 | I21: =SUMIF('Aug 2026'!$F$2:$F$150,'2026 Summary'!A21,'Aug 2026'!$G$2:$G$150) -> 0 | J21: =SUMIF('Sep 2026'!$F$2:$F$150,'2026 Summary'!A21,'Sep 2026'!$G$2:$G$150) -> 0 | K21: =SUMIF('Oct 2026'!$F$2:$F$150,'2026 Summary'!A21,'Oct 2026'!$G$2:$G$150) -> 0 | L21: =SUMIF('Nov 2026'!$F$2:$F$150,'2026 Summary'!A21,'Nov 2026'!$G$2:$G$150) -> 0 | M21: =SUMIF('Dec 2026'!$F$2:$F$150,'2026 Summary'!A21,'Dec 2026'!$G$2:$G$150) -> 0 | AA21: ='Jan 2026'!F20 -> 0
B22: =SUMIF('Jan 2026'!$F$2:$F$150,'2026 Summary'!A22,'Jan 2026'!$G$2:$G$150) -> 0 | C22: =SUMIF('Feb 2026'!$F$2:$F$150,'2026 Summary'!A22,'Feb 2026'!$G$2:$G$150) -> 0 | D22: =SUMIF('Mar 2026'!$F$2:$F$150,'2026 Summary'!A22,'Mar 2026'!$G$2:$G$150) -> 0 | E22: =SUMIF('Apr 2026'!$F$2:$F$150,'2026 Summary'!A22,'Apr 2026'!$G$2:$G$150) -> 0 | F22: =SUMIF('May 2026'!$F$2:$F$150,'2026 Summary'!A22,'May 2026'!$G$2:$G$150) -> 0 | G22: =SUMIF('Jun 2026'!$F$2:$F$150,'2026 Summary'!A22,'Jun 2026'!$G$2:$G$150) -> 0 | H22: =SUMIF('Jul 2026'!$F$2:$F$150,'2026 Summary'!A22,'Jul 2026'!$G$2:$G$150) -> 0 | I22: =SUMIF('Aug 2026'!$F$2:$F$150,'2026 Summary'!A22,'Aug 2026'!$G$2:$G$150) -> 0 | J22: =SUMIF('Sep 2026'!$F$2:$F$150,'2026 Summary'!A22,'Sep 2026'!$G$2:$G$150) -> 0 | K22: =SUMIF('Oct 2026'!$F$2:$F$150,'2026 Summary'!A22,'Oct 2026'!$G$2:$G$150) -> 0 | L22: =SUMIF('Nov 2026'!$F$2:$F$150,'2026 Summary'!A22,'Nov 2026'!$G$2:$G$150) -> 0 | M22: =SUMIF('Dec 2026'!$F$2:$F$150,'2026 Summary'!A22,'Dec 2026'!$G$2:$G$150) -> 0 | AA22: ='Jan 2026'!F21 -> 0
B23: =SUMIF('Jan 2026'!$F$2:$F$150,'2026 Summary'!A23,'Jan 2026'!$G$2:$G$150) -> 0 | C23: =SUMIF('Feb 2026'!$F$2:$F$150,'2026 Summary'!A23,'Feb 2026'!$G$2:$G$150) -> 0 | D23: =SUMIF('Mar 2026'!$F$2:$F$150,'2026 Summary'!A23,'Mar 2026'!$G$2:$G$150) -> 0 | E23: =SUMIF('Apr 2026'!$F$2:$F$150,'2026 Summary'!A23,'Apr 2026'!$G$2:$G$150) -> 0 | F23: =SUMIF('May 2026'!$F$2:$F$150,'2026 Summary'!A23,'May 2026'!$G$2:$G$150) -> 0 | G23: =SUMIF('Jun 2026'!$F$2:$F$150,'2026 Summary'!A23,'Jun 2026'!$G$2:$G$150) -> 0 | H23: =SUMIF('Jul 2026'!$F$2:$F$150,'2026 Summary'!A23,'Jul 2026'!$G$2:$G$150) -> 0 | I23: =SUMIF('Aug 2026'!$F$2:$F$150,'2026 Summary'!A23,'Aug 2026'!$G$2:$G$150) -> 0 | J23: =SUMIF('Sep 2026'!$F$2:$F$150,'2026 Summary'!A23,'Sep 2026'!$G$2:$G$150) -> 0 | K23: =SUMIF('Oct 2026'!$F$2:$F$150,'2026 Summary'!A23,'Oct 2026'!$G$2:$G$150) -> 0 | L23: =SUMIF('Nov 2026'!$F$2:$F$150,'2026 Summary'!A23,'Nov 2026'!$G$2:$G$150) -> 0 | M23: =SUMIF('Dec 2026'!$F$2:$F$150,'2026 Summary'!A23,'Dec 2026'!$G$2:$G$150) -> 0 | AA23: ='Jan 2026'!F22 -> 0
B24: =SUMIF('Jan 2026'!$F$2:$F$150,'2026 Summary'!A24,'Jan 2026'!$G$2:$G$150) -> 0 | C24: =SUMIF('Feb 2026'!$F$2:$F$150,'2026 Summary'!A24,'Feb 2026'!$G$2:$G$150) -> 0 | D24: =SUMIF('Mar 2026'!$F$2:$F$150,'2026 Summary'!A24,'Mar 2026'!$G$2:$G$150) -> 0 | E24: =SUMIF('Apr 2026'!$F$2:$F$150,'2026 Summary'!A24,'Apr 2026'!$G$2:$G$150) -> 0 | F24: =SUMIF('May 2026'!$F$2:$F$150,'2026 Summary'!A24,'May 2026'!$G$2:$G$150) -> 0 | G24: =SUMIF('Jun 2026'!$F$2:$F$150,'2026 Summary'!A24,'Jun 2026'!$G$2:$G$150) -> 0 | H24: =SUMIF('Jul 2026'!$F$2:$F$150,'2026 Summary'!A24,'Jul 2026'!$G$2:$G$150) -> 0 | I24: =SUMIF('Aug 2026'!$F$2:$F$150,'2026 Summary'!A24,'Aug 2026'!$G$2:$G$150) -> 0 | J24: =SUMIF('Sep 2026'!$F$2:$F$150,'2026 Summary'!A24,'Sep 2026'!$G$2:$G$150) -> 0 | K24: =SUMIF('Oct 2026'!$F$2:$F$150,'2026 Summary'!A24,'Oct 2026'!$G$2:$G$150) -> 0 | L24: =SUMIF('Nov 2026'!$F$2:$F$150,'2026 Summary'!A24,'Nov 2026'!$G$2:$G$150) -> 0 | M24: =SUMIF('Dec 2026'!$F$2:$F$150,'2026 Summary'!A24,'Dec 2026'!$G$2:$G$150) -> 0 | AA24: ='Jan 2026'!F23 -> 0
B25: =SUMIF('Jan 2026'!$F$2:$F$150,'2026 Summary'!A25,'Jan 2026'!$G$2:$G$150) -> 0 | C25: =SUMIF('Feb 2026'!$F$2:$F$150,'2026 Summary'!A25,'Feb 2026'!$G$2:$G$150) -> 0 | D25: =SUMIF('Mar 2026'!$F$2:$F$150,'2026 Summary'!A25,'Mar 2026'!$G$2:$G$150) -> 0 | E25: =SUMIF('Apr 2026'!$F$2:$F$150,'2026 Summary'!A25,'Apr 2026'!$G$2:$G$150) -> 0 | F25: =SUMIF('May 2026'!$F$2:$F$150,'2026 Summary'!A25,'May 2026'!$G$2:$G$150) -> 0 | G25: =SUMIF('Jun 2026'!$F$2:$F$150,'2026 Summary'!A25,'Jun 2026'!$G$2:$G$150) -> 0 | H25: =SUMIF('Jul 2026'!$F$2:$F$150,'2026 Summary'!A25,'Jul 2026'!$G$2:$G$150) -> 0 | I25: =SUMIF('Aug 2026'!$F$2:$F$150,'2026 Summary'!A25,'Aug 2026'!$G$2:$G$150) -> 0 | J25: =SUMIF('Sep 2026'!$F$2:$F$150,'2026 Summary'!A25,'Sep 2026'!$G$2:$G$150) -> 0 | K25: =SUMIF('Oct 2026'!$F$2:$F$150,'2026 Summary'!A25,'Oct 2026'!$G$2:$G$150) -> 0 | L25: =SUMIF('Nov 2026'!$F$2:$F$150,'2026 Summary'!A25,'Nov 2026'!$G$2:$G$150) -> 0 | M25: =SUMIF('Dec 2026'!$F$2:$F$150,'2026 Summary'!A25,'Dec 2026'!$G$2:$G$150) -> 0 | AA25: ='Jan 2026'!F24 -> 0
B26: =SUMIF('Jan 2026'!$F$2:$F$150,'2026 Summary'!A26,'Jan 2026'!$G$2:$G$150) -> 0 | C26: =SUMIF('Feb 2026'!$F$2:$F$150,'2026 Summary'!A26,'Feb 2026'!$G$2:$G$150) -> 0 | D26: =SUMIF('Mar 2026'!$F$2:$F$150,'2026 Summary'!A26,'Mar 2026'!$G$2:$G$150) -> 0 | E26: =SUMIF('Apr 2026'!$F$2:$F$150,'2026 Summary'!A26,'Apr 2026'!$G$2:$G$150) -> 0 | F26: =SUMIF('May 2026'!$F$2:$F$150,'2026 Summary'!A26,'May 2026'!$G$2:$G$150) -> 0 | G26: =SUMIF('Jun 2026'!$F$2:$F$150,'2026 Summary'!A26,'Jun 2026'!$G$2:$G$150) -> 0 | H26: =SUMIF('Jul 2026'!$F$2:$F$150,'2026 Summary'!A26,'Jul 2026'!$G$2:$G$150) -> 0 | I26: =SUMIF('Aug 2026'!$F$2:$F$150,'2026 Summary'!A26,'Aug 2026'!$G$2:$G$150) -> 0 | J26: =SUMIF('Sep 2026'!$F$2:$F$150,'2026 Summary'!A26,'Sep 2026'!$G$2:$G$150) -> 0 | K26: =SUMIF('Oct 2026'!$F$2:$F$150,'2026 Summary'!A26,'Oct 2026'!$G$2:$G$150) -> 0 | L26: =SUMIF('Nov 2026'!$F$2:$F$150,'2026 Summary'!A26,'Nov 2026'!$G$2:$G$150) -> 0 | M26: =SUMIF('Dec 2026'!$F$2:$F$150,'2026 Summary'!A26,'Dec 2026'!$G$2:$G$150) -> 0 | AA26: ='Jan 2026'!F25 -> 0
B27: =SUMIF('Jan 2026'!$F$2:$F$150,'2026 Summary'!A27,'Jan 2026'!$G$2:$G$150) -> 0 | C27: =SUMIF('Feb 2026'!$F$2:$F$150,'2026 Summary'!A27,'Feb 2026'!$G$2:$G$150) -> 0 | D27: =SUMIF('Mar 2026'!$F$2:$F$150,'2026 Summary'!A27,'Mar 2026'!$G$2:$G$150) -> 0 | E27: =SUMIF('Apr 2026'!$F$2:$F$150,'2026 Summary'!A27,'Apr 2026'!$G$2:$G$150) -> 0 | F27: =SUMIF('May 2026'!$F$2:$F$150,'2026 Summary'!A27,'May 2026'!$G$2:$G$150) -> 0 | G27: =SUMIF('Jun 2026'!$F$2:$F$150,'2026 Summary'!A27,'Jun 2026'!$G$2:$G$150) -> 0 | H27: =SUMIF('Jul 2026'!$F$2:$F$150,'2026 Summary'!A27,'Jul 2026'!$G$2:$G$150) -> 0 | I27: =SUMIF('Aug 2026'!$F$2:$F$150,'2026 Summary'!A27,'Aug 2026'!$G$2:$G$150) -> 0 | J27: =SUMIF('Sep 2026'!$F$2:$F$150,'2026 Summary'!A27,'Sep 2026'!$G$2:$G$150) -> 0 | K27: =SUMIF('Oct 2026'!$F$2:$F$150,'2026 Summary'!A27,'Oct 2026'!$G$2:$G$150) -> 0 | L27: =SUMIF('Nov 2026'!$F$2:$F$150,'2026 Summary'!A27,'Nov 2026'!$G$2:$G$150) -> 0 | M27: =SUMIF('Dec 2026'!$F$2:$F$150,'2026 Summary'!A27,'Dec 2026'!$G$2:$G$150) -> 0 | AA27: ='Jan 2026'!F26 -> 0
B28: =SUMIF('Jan 2026'!$F$2:$F$150,'2026 Summary'!A28,'Jan 2026'!$G$2:$G$150) -> 0 | C28: =SUMIF('Feb 2026'!$F$2:$F$150,'2026 Summary'!A28,'Feb 2026'!$G$2:$G$150) -> 0 | D28: =SUMIF('Mar 2026'!$F$2:$F$150,'2026 Summary'!A28,'Mar 2026'!$G$2:$G$150) -> 0 | E28: =SUMIF('Apr 2026'!$F$2:$F$150,'2026 Summary'!A28,'Apr 2026'!$G$2:$G$150) -> 0 | F28: =SUMIF('May 2026'!$F$2:$F$150,'2026 Summary'!A28,'May 2026'!$G$2:$G$150) -> 0 | G28: =SUMIF('Jun 2026'!$F$2:$F$150,'2026 Summary'!A28,'Jun 2026'!$G$2:$G$150) -> 0 | H28: =SUMIF('Jul 2026'!$F$2:$F$150,'2026 Summary'!A28,'Jul 2026'!$G$2:$G$150) -> 0 | I28: =SUMIF('Aug 2026'!$F$2:$F$150,'2026 Summary'!A28,'Aug 2026'!$G$2:$G$150) -> 0 | J28: =SUMIF('Sep 2026'!$F$2:$F$150,'2026 Summary'!A28,'Sep 2026'!$G$2:$G$150) -> 0 | K28: =SUMIF('Oct 2026'!$F$2:$F$150,'2026 Summary'!A28,'Oct 2026'!$G$2:$G$150) -> 0 | L28: =SUMIF('Nov 2026'!$F$2:$F$150,'2026 Summary'!A28,'Nov 2026'!$G$2:$G$150) -> 0 | M28: =SUMIF('Dec 2026'!$F$2:$F$150,'2026 Summary'!A28,'Dec 2026'!$G$2:$G$150) -> 0 | AA28: ='Jan 2026'!F27 -> 0
B29: =SUMIF('Jan 2026'!$F$2:$F$150,'2026 Summary'!A29,'Jan 2026'!$G$2:$G$150) -> 0 | C29: =SUMIF('Feb 2026'!$F$2:$F$150,'2026 Summary'!A29,'Feb 2026'!$G$2:$G$150) -> 0 | D29: =SUMIF('Mar 2026'!$F$2:$F$150,'2026 Summary'!A29,'Mar 2026'!$G$2:$G$150) -> 0 | E29: =SUMIF('Apr 2026'!$F$2:$F$150,'2026 Summary'!A29,'Apr 2026'!$G$2:$G$150) -> 0 | F29: =SUMIF('May 2026'!$F$2:$F$150,'2026 Summary'!A29,'May 2026'!$G$2:$G$150) -> 0 | G29: =SUMIF('Jun 2026'!$F$2:$F$150,'2026 Summary'!A29,'Jun 2026'!$G$2:$G$150) -> 0 | H29: =SUMIF('Jul 2026'!$F$2:$F$150,'2026 Summary'!A29,'Jul 2026'!$G$2:$G$150) -> 0 | I29: =SUMIF('Aug 2026'!$F$2:$F$150,'2026 Summary'!A29,'Aug 2026'!$G$2:$G$150) -> 0 | J29: =SUMIF('Sep 2026'!$F$2:$F$150,'2026 Summary'!A29,'Sep 2026'!$G$2:$G$150) -> 0 | K29: =SUMIF('Oct 2026'!$F$2:$F$150,'2026 Summary'!A29,'Oct 2026'!$G$2:$G$150) -> 0 | L29: =SUMIF('Nov 2026'!$F$2:$F$150,'2026 Summary'!A29,'Nov 2026'!$G$2:$G$150) -> 0 | M29: =SUMIF('Dec 2026'!$F$2:$F$150,'2026 Summary'!A29,'Dec 2026'!$G$2:$G$150) -> 0 | AA29: ='Jan 2026'!F28 -> 0
B30: =SUMIF('Jan 2026'!$F$2:$F$150,'2026 Summary'!A30,'Jan 2026'!$G$2:$G$150) -> 0 | C30: =SUMIF('Feb 2026'!$F$2:$F$150,'2026 Summary'!A30,'Feb 2026'!$G$2:$G$150) -> 0 | D30: =SUMIF('Mar 2026'!$F$2:$F$150,'2026 Summary'!A30,'Mar 2026'!$G$2:$G$150) -> 0 | E30: =SUMIF('Apr 2026'!$F$2:$F$150,'2026 Summary'!A30,'Apr 2026'!$G$2:$G$150) -> 0 | F30: =SUMIF('May 2026'!$F$2:$F$150,'2026 Summary'!A30,'May 2026'!$G$2:$G$150) -> 0 | G30: =SUMIF('Jun 2026'!$F$2:$F$150,'2026 Summary'!A30,'Jun 2026'!$G$2:$G$150) -> 0 | H30: =SUMIF('Jul 2026'!$F$2:$F$150,'2026 Summary'!A30,'Jul 2026'!$G$2:$G$150) -> 0 | I30: =SUMIF('Aug 2026'!$F$2:$F$150,'2026 Summary'!A30,'Aug 2026'!$G$2:$G$150) -> 0 | J30: =SUMIF('Sep 2026'!$F$2:$F$150,'2026 Summary'!A30,'Sep 2026'!$G$2:$G$150) -> 0 | K30: =SUMIF('Oct 2026'!$F$2:$F$150,'2026 Summary'!A30,'Oct 2026'!$G$2:$G$150) -> 0 | L30: =SUMIF('Nov 2026'!$F$2:$F$150,'2026 Summary'!A30,'Nov 2026'!$G$2:$G$150) -> 0 | M30: =SUMIF('Dec 2026'!$F$2:$F$150,'2026 Summary'!A30,'Dec 2026'!$G$2:$G$150) -> 0 | AA30: ='Jan 2026'!F29 -> 0
B31: =SUMIF('Jan 2026'!$F$2:$F$150,'2026 Summary'!A31,'Jan 2026'!$G$2:$G$150) -> 0 | C31: =SUMIF('Feb 2026'!$F$2:$F$150,'2026 Summary'!A31,'Feb 2026'!$G$2:$G$150) -> 0 | D31: =SUMIF('Mar 2026'!$F$2:$F$150,'2026 Summary'!A31,'Mar 2026'!$G$2:$G$150) -> 0 | E31: =SUMIF('Apr 2026'!$F$2:$F$150,'2026 Summary'!A31,'Apr 2026'!$G$2:$G$150) -> 0 | F31: =SUMIF('May 2026'!$F$2:$F$150,'2026 Summary'!A31,'May 2026'!$G$2:$G$150) -> 0 | G31: =SUMIF('Jun 2026'!$F$2:$F$150,'2026 Summary'!A31,'Jun 2026'!$G$2:$G$150) -> 0 | H31: =SUMIF('Jul 2026'!$F$2:$F$150,'2026 Summary'!A31,'Jul 2026'!$G$2:$G$150) -> 0 | I31: =SUMIF('Aug 2026'!$F$2:$F$150,'2026 Summary'!A31,'Aug 2026'!$G$2:$G$150) -> 0 | J31: =SUMIF('Sep 2026'!$F$2:$F$150,'2026 Summary'!A31,'Sep 2026'!$G$2:$G$150) -> 0 | K31: =SUMIF('Oct 2026'!$F$2:$F$150,'2026 Summary'!A31,'Oct 2026'!$G$2:$G$150) -> 0 | L31: =SUMIF('Nov 2026'!$F$2:$F$150,'2026 Summary'!A31,'Nov 2026'!$G$2:$G$150) -> 0 | M31: =SUMIF('Dec 2026'!$F$2:$F$150,'2026 Summary'!A31,'Dec 2026'!$G$2:$G$150) -> 0 | AA31: ='Jan 2026'!F30 -> 0
... B87: =SUMIF('Jan 2026'!$F$2:$F$150,'2026 Summary'!A87,'Jan 2026'!$G$2:$G$150) -> 0 | C87: =SUMIF('Feb 2026'!$F$2:$F$150,'2026 Summary'!A87,'Feb 2026'!$G$2:$G$150) -> 0 | D87: =SUMIF('Mar 2026'!$F$2:$F$150,'2026 Summary'!A87,'Mar 2026'!$G$2:$G$150) -> 0 | E87: =SUMIF('Apr 2026'!$F$2:$F$150,'2026 Summary'!A87,'Apr 2026'!$G$2:$G$150) -> 0 | F87: =SUMIF('May 2026'!$F$2:$F$150,'2026 Summary'!A87,'May 2026'!$G$2:$G$150) -> 0 | G87: =SUMIF('Jun 2026'!$F$2:$F$150,'2026 Summary'!A87,'Jun 2026'!$G$2:$G$150) -> 0 | H87: =SUMIF('Jul 2026'!$F$2:$F$150,'2026 Summary'!A87,'Jul 2026'!$G$2:$G$150) -> 0 | I87: =SUMIF('Aug 2026'!$F$2:$F$150,'2026 Summary'!A87,'Aug 2026'!$G$2:$G$150) -> 0 | J87: =SUMIF('Sep 2026'!$F$2:$F$150,'2026 Summary'!A87,'Sep 2026'!$G$2:$G$150) -> 0 | K87: =SUMIF('Oct 2026'!$F$2:$F$150,'2026 Summary'!A87,'Oct 2026'!$G$2:$G$150) -> 0 | L87: =SUMIF('Nov 2026'!$F$2:$F$150,'2026 Summary'!A87,'Nov 2026'!$G$2:$G$150) -> 0 | M87: =SUMIF('Dec 2026'!$F$2:$F$150,'2026 Summary'!A87,'Dec 2026'!$G$2:$G$150) -> 0 | AA87: ='Jan 2026'!F86 -> 0
AA88: ='Jan 2026'!F87 -> 0
AA89: ='Jan 2026'!F88 -> 0
AA90: ='Jan 2026'!F89 -> 0
AA91: ='Jan 2026'!F90 -> 0
AA92: ='Jan 2026'!F91 -> 0
AA93: ='Jan 2026'!F92 -> 0
AA94: ='Jan 2026'!F93 -> 0
AA95: ='Jan 2026'!F94 -> 0
...

Sheet Jan 2026
A1: Date | B1: Asset Manager | C1: Company | D1: Value | F1: Summary | G1: Value | H1: Lists | M1: List | N1: Value
A2: 46023 | F2: {=_xlfn._xlws.SORT(_xlfn.UNIQUE(C2:C150))} -> 0 | G2: =SUMIF($C$2:$C$150,F2,$D$2:$D$150) -> 0 | M2: UN Blacklist 2023 | N2: =SUMIF($H$2:$H$150,"*UN Blacklist 2023*",$G$2:$G$150) -> 0
G3: =SUMIF($C$2:$C$150,F3,$D$2:$D$150) -> 0 | M3: UN Blacklist 2025 | N3: =SUMIF($H$2:$H$150,"*UN Blacklist 2025*",$G$2:$G$150) -> 0
G4: =SUMIF($C$2:$C$150,F4,$D$2:$D$150) -> 0 | M4: AFSC Divestment List 2025 | N4: =SUMIF($H$2:$H$97150,"*AFSC Divestment List 2025*",$G$2:$G$150) -> 0
G5: =SUMIF($C$2:$C$150,F5,$D$2:$D$150) -> 0 | M5: WhoProfits | N5: =SUMIF($H$2:$H$150,"*Who Profits*",$G$2:$G$150) -> 0
G6: =SUMIF($C$2:$C$150,F6,$D$2:$D$150) -> 0
G7: =SUMIF($C$2:$C$150,F7,$D$2:$D$150) -> 0 | M7: Bank | N7: Value
G8: =SUMIF($C$2:$C$150,F8,$D$2:$D$150) -> 0 | M8: Danske Bank | N8: =SUMIF($B$2:$B$150,"*Danske Bank*",$D$2:$D$150) -> 0
G9: =SUMIF($C$2:$C$150,F9,$D$2:$D$150) -> 0 | M9: Jyske Bank | N9: =SUMIF($B$2:$B$150,"*Jyske Bank*",$D$2:$D$150) -> 0
G10: =SUMIF($C$2:$C$150,F10,$D$2:$D$150) -> 0 | M10: SEB | N10: =SUMIF($B$2:$B$150,"*SEB*",$D$2:$D$150) -> 0
G11: =SUMIF($C$2:$C$150,F11,$D$2:$D$150) -> 0
G12: =SUMIF($C$2:$C$150,F12,$D$2:$D$150) -> 0 | M12: Total
G13: =SUMIF($C$2:$C$150,F13,$D$2:$D$150) -> 0 | M13: =SUM(D2:D150) -> 0
G14: =SUMIF($C$2:$C$150,F14,$D$2:$D$150) -> 0
G15: =SUMIF($C$2:$C$150,F15,$D$2:$D$150) -> 0
G16: =SUMIF($C$2:$C$150,F16,$D$2:$D$150) -> 0
G17: =SUMIF($C$2:$C$150,F17,$D$2:$D$150) -> 0
G18: =SUMIF($C$2:$C$150,F18,$D$2:$D$150) -> 0
G19: =SUMIF($C$2:$C$150,F19,$D$2:$D$150) -> 0
G20: =SUMIF($C$2:$C$150,F20,$D$2:$D$150) -> 0
G21: =SUMIF($C$2:$C$150,F21,$D$2:$D$150) -> 0
G22: =SUMIF($C$2:$C$150,F22,$D$2:$D$150) -> 0
G23: =SUMIF($C$2:$C$150,F23,$D$2:$D$150) -> 0
G24: =SUMIF($C$2:$C$150,F24,$D$2:$D$150) -> 0
G25: =SUMIF($C$2:$C$150,F25,$D$2:$D$150) -> 0
... G151: =SUMIF($C$2:$C$150,F151,$D$2:$D$150) -> 0

Sheet Feb 2026
A1: Date | B1: Asset Manager | C1: Company | D1: Value | F1: Summary | G1: Value | H1: Lists | M1: List | N1: Value
A2: 46054 | F2: {=_xlfn._xlws.SORT(_xlfn.UNIQUE(C2:C150))} -> 0 | G2: =SUMIF($C$2:$C$150,F2,$D$2:$D$150) -> 0 | M2: UN Blacklist 2023 | N2: =SUMIF($H$2:$H$150,"*UN Blacklist 2023*",$G$2:$G$150) -> 0
G3: =SUMIF($C$2:$C$150,F3,$D$2:$D$150) -> 0 | M3: UN Blacklist 2025 | N3: =SUMIF($H$2:$H$150,"*UN Blacklist 2025*",$G$2:$G$150) -> 0
G4: =SUMIF($C$2:$C$150,F4,$D$2:$D$150) -> 0 | M4: AFSC Divestment List 2025 | N4: =SUMIF($H$2:$H$97150,"*AFSC Divestment List 2025*",$G$2:$G$150) -> 0
G5: =SUMIF($C$2:$C$150,F5,$D$2:$D$150) -> 0 | M5: WhoProfits | N5: =SUMIF($H$2:$H$150,"*Who Profits*",$G$2:$G$150) -> 0
G6: =SUMIF($C$2:$C$150,F6,$D$2:$D$150) -> 0
G7: =SUMIF($C$2:$C$150,F7,$D$2:$D$150) -> 0 | M7: Bank | N7: Value
G8: =SUMIF($C$2:$C$150,F8,$D$2:$D$150) -> 0 | M8: Danske Bank | N8: =SUMIF($B$2:$B$150,"*Danske Bank*",$D$2:$D$150) -> 0
G9: =SUMIF($C$2:$C$150,F9,$D$2:$D$150) -> 0 | M9: Jyske Bank | N9: =SUMIF($B$2:$B$150,"*Jyske Bank*",$D$2:$D$150) -> 0
G10: =SUMIF($C$2:$C$150,F10,$D$2:$D$150) -> 0 | M10: SEB | N10: =SUMIF($B$2:$B$150,"*SEB*",$D$2:$D$150) -> 0
G11: =SUMIF($C$2:$C$150,F11,$D$2:$D$150) -> 0
G12: =SUMIF($C$2:$C$150,F12,$D$2:$D$150) -> 0 | M12: Total
G13: =SUMIF($C$2:$C$150,F13,$D$2:$D$150) -> 0 | M13: =SUM(D2:D150) -> 0
G14: =SUMIF($C$2:$C$150,F14,$D$2:$D$150) -> 0
G15: =SUMIF($C$2:$C$150,F15,$D$2:$D$150) -> 0
G16: =SUMIF($C$2:$C$150,F16,$D$2:$D$150) -> 0
G17: =SUMIF($C$2:$C$150,F17,$D$2:$D$150) -> 0
G18: =SUMIF($C$2:$C$150,F18,$D$2:$D$150) -> 0
G19: =SUMIF($C$2:$C$150,F19,$D$2:$D$150) -> 0
G20: =SUMIF($C$2:$C$150,F20,$D$2:$D$150) -> 0
G21: =SUMIF($C$2:$C$150,F21,$D$2:$D$150) -> 0
G22: =SUMIF($C$2:$C$150,F22,$D$2:$D$150) -> 0
G23: =SUMIF($C$2:$C$150,F23,$D$2:$D$150) -> 0
G24: =SUMIF($C$2:$C$150,F24,$D$2:$D$150) -> 0
G25: =SUMIF($C$2:$C$150,F25,$D$2:$D$150) -> 0
... G151: =SUMIF($C$2:$C$150,F151,$D$2:$D$150) -> 0

Sheet Mar 2026
A1: Date | B1: Asset Manager | C1: Company | D1: Value | F1: Summary | G1: Value | H1: Lists | M1: List | N1: Value
A2: 46082 | F2: {=_xlfn._xlws.SORT(_xlfn.UNIQUE(C2:C150))} -> 0 | G2: =SUMIF($C$2:$C$150,F2,$D$2:$D$150) -> 0 | M2: UN Blacklist 2023 | N2: =SUMIF($H$2:$H$150,"*UN Blacklist 2023*",$G$2:$G$150) -> 0
G3: =SUMIF($C$2:$C$150,F3,$D$2:$D$150) -> 0 | M3: UN Blacklist 2025 | N3: =SUMIF($H$2:$H$150,"*UN Blacklist 2025*",$G$2:$G$150) -> 0
G4: =SUMIF($C$2:$C$150,F4,$D$2:$D$150) -> 0 | M4: AFSC Divestment List 2025 | N4: =SUMIF($H$2:$H$97150,"*AFSC Divestment List 2025*",$G$2:$G$150) -> 0
G5: =SUMIF($C$2:$C$150,F5,$D$2:$D$150) -> 0 | M5: WhoProfits | N5: =SUMIF($H$2:$H$150,"*Who Profits*",$G$2:$G$150) -> 0
G6: =SUMIF($C$2:$C$150,F6,$D$2:$D$150) -> 0
G7: =SUMIF($C$2:$C$150,F7,$D$2:$D$150) -> 0 | M7: Bank | N7: Value
G8: =SUMIF($C$2:$C$150,F8,$D$2:$D$150) -> 0 | M8: Danske Bank | N8: =SUMIF($B$2:$B$150,"*Danske Bank*",$D$2:$D$150) -> 0
G9: =SUMIF($C$2:$C$150,F9,$D$2:$D$150) -> 0 | M9: Jyske Bank | N9: =SUMIF($B$2:$B$150,"*Jyske Bank*",$D$2:$D$150) -> 0
G10: =SUMIF($C$2:$C$150,F10,$D$2:$D$150) -> 0 | M10: SEB | N10: =SUMIF($B$2:$B$150,"*SEB*",$D$2:$D$150) -> 0
G11: =SUMIF($C$2:$C$150,F11,$D$2:$D$150) -> 0
G12: =SUMIF($C$2:$C$150,F12,$D$2:$D$150) -> 0 | M12: Total
G13: =SUMIF($C$2:$C$150,F13,$D$2:$D$150) -> 0 | M13: =SUM(D2:D150) -> 0
G14: =SUMIF($C$2:$C$150,F14,$D$2:$D$150) -> 0
G15: =SUMIF($C$2:$C$150,F15,$D$2:$D$150) -> 0
G16: =SUMIF($C$2:$C$150,F16,$D$2:$D$150) -> 0
G17: =SUMIF($C$2:$C$150,F17,$D$2:$D$150) -> 0
G18: =SUMIF($C$2:$C$150,F18,$D$2:$D$150) -> 0
G19: =SUMIF($C$2:$C$150,F19,$D$2:$D$150) -> 0
G20: =SUMIF($C$2:$C$150,F20,$D$2:$D$150) -> 0
G21: =SUMIF($C$2:$C$150,F21,$D$2:$D$150) -> 0
G22: =SUMIF($C$2:$C$150,F22,$D$2:$D$150) -> 0
G23: =SUMIF($C$2:$C$150,F23,$D$2:$D$150) -> 0
G24: =SUMIF($C$2:$C$150,F24,$D$2:$D$150) -> 0
G25: =SUMIF($C$2:$C$150,F25,$D$2:$D$150) -> 0
... G151: =SUMIF($C$2:$C$150,F151,$D$2:$D$150) -> 0

Sheet Apr 2026
A1: Date | B1: Asset Manager | C1: Company | D1: Value | F1: Summary | G1: Value | H1: Lists | M1: List | N1: Value
A2: 46113 | F2: {=_xlfn._xlws.SORT(_xlfn.UNIQUE(C2:C150))} -> 0 | G2: =SUMIF($C$2:$C$150,F2,$D$2:$D$150) -> 0 | M2: UN Blacklist 2023 | N2: =SUMIF($H$2:$H$150,"*UN Blacklist 2023*",$G$2:$G$150) -> 0
G3: =SUMIF($C$2:$C$150,F3,$D$2:$D$150) -> 0 | M3: UN Blacklist 2025 | N3: =SUMIF($H$2:$H$150,"*UN Blacklist 2025*",$G$2:$G$150) -> 0
G4: =SUMIF($C$2:$C$150,F4,$D$2:$D$150) -> 0 | M4: AFSC Divestment List 2025 | N4: =SUMIF($H$2:$H$97150,"*AFSC Divestment List 2025*",$G$2:$G$150) -> 0
G5: =SUMIF($C$2:$C$150,F5,$D$2:$D$150) -> 0 | M5: WhoProfits | N5: =SUMIF($H$2:$H$150,"*Who Profits*",$G$2:$G$150) -> 0
G6: =SUMIF($C$2:$C$150,F6,$D$2:$D$150) -> 0
G7: =SUMIF($C$2:$C$150,F7,$D$2:$D$150) -> 0 | M7: Bank | N7: Value
G8: =SUMIF($C$2:$C$150,F8,$D$2:$D$150) -> 0 | M8: Danske Bank | N8: =SUMIF($B$2:$B$150,"*Danske Bank*",$D$2:$D$150) -> 0
G9: =SUMIF($C$2:$C$150,F9,$D$2:$D$150) -> 0 | M9: Jyske Bank | N9: =SUMIF($B$2:$B$150,"*Jyske Bank*",$D$2:$D$150) -> 0
G10: =SUMIF($C$2:$C$150,F10,$D$2:$D$150) -> 0 | M10: SEB | N10: =SUMIF($B$2:$B$150,"*SEB*",$D$2:$D$150) -> 0
G11: =SUMIF($C$2:$C$150,F11,$D$2:$D$150) -> 0
G12: =SUMIF($C$2:$C$150,F12,$D$2:$D$150) -> 0 | M12: Total
G13: =SUMIF($C$2:$C$150,F13,$D$2:$D$150) -> 0 | M13: =SUM(D2:D150) -> 0
G14: =SUMIF($C$2:$C$150,F14,$D$2:$D$150) -> 0
G15: =SUMIF($C$2:$C$150,F15,$D$2:$D$150) -> 0
G16: =SUMIF($C$2:$C$150,F16,$D$2:$D$150) -> 0
G17: =SUMIF($C$2:$C$150,F17,$D$2:$D$150) -> 0
G18: =SUMIF($C$2:$C$150,F18,$D$2:$D$150) -> 0
G19: =SUMIF($C$2:$C$150,F19,$D$2:$D$150) -> 0
G20: =SUMIF($C$2:$C$150,F20,$D$2:$D$150) -> 0
G21: =SUMIF($C$2:$C$150,F21,$D$2:$D$150) -> 0
G22: =SUMIF($C$2:$C$150,F22,$D$2:$D$150) -> 0
G23: =SUMIF($C$2:$C$150,F23,$D$2:$D$150) -> 0
G24: =SUMIF($C$2:$C$150,F24,$D$2:$D$150) -> 0
G25: =SUMIF($C$2:$C$150,F25,$D$2:$D$150) -> 0
... G150: =SUMIF($C$2:$C$150,F150,$D$2:$D$150) -> 0

Sheet May 2026
A1: Date | B1: Asset Manager | C1: Company | D1: Value | F1: Summary | G1: Value | H1: Lists | M1: List | N1: Value
A2: 46143 | F2: {=_xlfn._xlws.SORT(_xlfn.UNIQUE(C2:C150))} -> 0 | G2: =SUMIF($C$2:$C$150,F2,$D$2:$D$150) -> 0 | M2: UN Blacklist 2023 | N2: =SUMIF($H$2:$H$150,"*UN Blacklist 2023*",$G$2:$G$150) -> 0
G3: =SUMIF($C$2:$C$150,F3,$D$2:$D$150) -> 0 | M3: UN Blacklist 2025 | N3: =SUMIF($H$2:$H$150,"*UN Blacklist 2025*",$G$2:$G$150) -> 0
G4: =SUMIF($C$2:$C$150,F4,$D$2:$D$150) -> 0 | M4: AFSC Divestment List 2025 | N4: =SUMIF($H$2:$H$97150,"*AFSC Divestment List 2025*",$G$2:$G$150) -> 0
G5: =SUMIF($C$2:$C$150,F5,$D$2:$D$150) -> 0 | M5: WhoProfits | N5: =SUMIF($H$2:$H$150,"*Who Profits*",$G$2:$G$150) -> 0
G6: =SUMIF($C$2:$C$150,F6,$D$2:$D$150) -> 0
G7: =SUMIF($C$2:$C$150,F7,$D$2:$D$150) -> 0 | M7: Bank | N7: Value
G8: =SUMIF($C$2:$C$150,F8,$D$2:$D$150) -> 0 | M8: Danske Bank | N8: =SUMIF($B$2:$B$150,"*Danske Bank*",$D$2:$D$150) -> 0
G9: =SUMIF($C$2:$C$150,F9,$D$2:$D$150) -> 0 | M9: Jyske Bank | N9: =SUMIF($B$2:$B$150,"*Jyske Bank*",$D$2:$D$150) -> 0
G10: =SUMIF($C$2:$C$150,F10,$D$2:$D$150) -> 0 | M10: SEB | N10: =SUMIF($B$2:$B$150,"*SEB*",$D$2:$D$150) -> 0
G11: =SUMIF($C$2:$C$150,F11,$D$2:$D$150) -> 0
G12: =SUMIF($C$2:$C$150,F12,$D$2:$D$150) -> 0 | M12: Total
G13: =SUMIF($C$2:$C$150,F13,$D$2:$D$150) -> 0 | M13: =SUM(D2:D150) -> 0
G14: =SUMIF($C$2:$C$150,F14,$D$2:$D$150) -> 0
G15: =SUMIF($C$2:$C$150,F15,$D$2:$D$150) -> 0
G16: =SUMIF($C$2:$C$150,F16,$D$2:$D$150) -> 0
G17: =SUMIF($C$2:$C$150,F17,$D$2:$D$150) -> 0
G18: =SUMIF($C$2:$C$150,F18,$D$2:$D$150) -> 0
G19: =SUMIF($C$2:$C$150,F19,$D$2:$D$150) -> 0
G20: =SUMIF($C$2:$C$150,F20,$D$2:$D$150) -> 0
G21: =SUMIF($C$2:$C$150,F21,$D$2:$D$150) -> 0
G22: =SUMIF($C$2:$C$150,F22,$D$2:$D$150) -> 0
G23: =SUMIF($C$2:$C$150,F23,$D$2:$D$150) -> 0
G24: =SUMIF($C$2:$C$150,F24,$D$2:$D$150) -> 0
G25: =SUMIF($C$2:$C$150,F25,$D$2:$D$150) -> 0
... G151: =SUMIF($C$2:$C$150,F151,$D$2:$D$150) -> 0

Sheet Jun 2026
A1: Date | B1: Asset Manager | C1: Company | D1: Value | F1: Summary | G1: Value | H1: Lists | M1: List | N1: Value
A2: 46174 | F2: {=_xlfn._xlws.SORT(_xlfn.UNIQUE(C2:C150))} -> 0 | G2: =SUMIF($C$2:$C$150,F2,$D$2:$D$150) -> 0 | M2: UN Blacklist 2023 | N2: =SUMIF($H$2:$H$150,"*UN Blacklist 2023*",$G$2:$G$150) -> 0
G3: =SUMIF($C$2:$C$150,F3,$D$2:$D$150) -> 0 | M3: UN Blacklist 2025 | N3: =SUMIF($H$2:$H$150,"*UN Blacklist 2025*",$G$2:$G$150) -> 0
G4: =SUMIF($C$2:$C$150,F4,$D$2:$D$150) -> 0 | M4: AFSC Divestment List 2025 | N4: =SUMIF($H$2:$H$97150,"*AFSC Divestment List 2025*",$G$2:$G$150) -> 0
G5: =SUMIF($C$2:$C$150,F5,$D$2:$D$150) -> 0 | M5: WhoProfits | N5: =SUMIF($H$2:$H$150,"*Who Profits*",$G$2:$G$150) -> 0
G6: =SUMIF($C$2:$C$150,F6,$D$2:$D$150) -> 0
G7: =SUMIF($C$2:$C$150,F7,$D$2:$D$150) -> 0 | M7: Bank | N7: Value
G8: =SUMIF($C$2:$C$150,F8,$D$2:$D$150) -> 0 | M8: Danske Bank | N8: =SUMIF($B$2:$B$150,"*Danske Bank*",$D$2:$D$150) -> 0
G9: =SUMIF($C$2:$C$150,F9,$D$2:$D$150) -> 0 | M9: Jyske Bank | N9: =SUMIF($B$2:$B$150,"*Jyske Bank*",$D$2:$D$150) -> 0
G10: =SUMIF($C$2:$C$150,F10,$D$2:$D$150) -> 0 | M10: SEB | N10: =SUMIF($B$2:$B$150,"*SEB*",$D$2:$D$150) -> 0
G11: =SUMIF($C$2:$C$150,F11,$D$2:$D$150) -> 0
G12: =SUMIF($C$2:$C$150,F12,$D$2:$D$150) -> 0 | M12: Total
G13: =SUMIF($C$2:$C$150,F13,$D$2:$D$150) -> 0 | M13: =SUM(D2:D150) -> 0
G14: =SUMIF($C$2:$C$150,F14,$D$2:$D$150) -> 0
G15: =SUMIF($C$2:$C$150,F15,$D$2:$D$150) -> 0
G16: =SUMIF($C$2:$C$150,F16,$D$2:$D$150) -> 0
G17: =SUMIF($C$2:$C$150,F17,$D$2:$D$150) -> 0
G18: =SUMIF($C$2:$C$150,F18,$D$2:$D$150) -> 0
G19: =SUMIF($C$2:$C$150,F19,$D$2:$D$150) -> 0
G20: =SUMIF($C$2:$C$150,F20,$D$2:$D$150) -> 0
G21: =SUMIF($C$2:$C$150,F21,$D$2:$D$150) -> 0
G22: =SUMIF($C$2:$C$150,F22,$D$2:$D$150) -> 0
G23: =SUMIF($C$2:$C$150,F23,$D$2:$D$150) -> 0
G24: =SUMIF($C$2:$C$150,F24,$D$2:$D$150) -> 0
G25: =SUMIF($C$2:$C$150,F25,$D$2:$D$150) -> 0
... G151: =SUMIF($C$2:$C$150,F151,$D$2:$D$150) -> 0

Sheet Jul 2026
A1: Date | B1: Asset Manager | C1: Company | D1: Value | F1: Summary | G1: Value | H1: Lists | M1: List | N1: Value
A2: 46204 | F2: {=_xlfn._xlws.SORT(_xlfn.UNIQUE(C2:C150))} -> 0 | G2: =SUMIF($C$2:$C$150,F2,$D$2:$D$150) -> 0 | M2: UN Blacklist 2023 | N2: =SUMIF($H$2:$H$150,"*UN Blacklist 2023*",$G$2:$G$150) -> 0
G3: =SUMIF($C$2:$C$150,F3,$D$2:$D$150) -> 0 | M3: UN Blacklist 2025 | N3: =SUMIF($H$2:$H$150,"*UN Blacklist 2025*",$G$2:$G$150) -> 0
G4: =SUMIF($C$2:$C$150,F4,$D$2:$D$150) -> 0 | M4: AFSC Divestment List 2025 | N4: =SUMIF($H$2:$H$97150,"*AFSC Divestment List 2025*",$G$2:$G$150) -> 0
G5: =SUMIF($C$2:$C$150,F5,$D$2:$D$150) -> 0 | M5: WhoProfits | N5: =SUMIF($H$2:$H$150,"*Who Profits*",$G$2:$G$150) -> 0
G6: =SUMIF($C$2:$C$150,F6,$D$2:$D$150) -> 0
G7: =SUMIF($C$2:$C$150,F7,$D$2:$D$150) -> 0 | M7: Bank | N7: Value
G8: =SUMIF($C$2:$C$150,F8,$D$2:$D$150) -> 0 | M8: Danske Bank | N8: =SUMIF($B$2:$B$150,"*Danske Bank*",$D$2:$D$150) -> 0
G9: =SUMIF($C$2:$C$150,F9,$D$2:$D$150) -> 0 | M9: Jyske Bank | N9: =SUMIF($B$2:$B$150,"*Jyske Bank*",$D$2:$D$150) -> 0
G10: =SUMIF($C$2:$C$150,F10,$D$2:$D$150) -> 0 | M10: SEB | N10: =SUMIF($B$2:$B$150,"*SEB*",$D$2:$D$150) -> 0
G11: =SUMIF($C$2:$C$150,F11,$D$2:$D$150) -> 0
G12: =SUMIF($C$2:$C$150,F12,$D$2:$D$150) -> 0 | M12: Total
G13: =SUMIF($C$2:$C$150,F13,$D$2:$D$150) -> 0 | M13: =SUM(D2:D150) -> 0
G14: =SUMIF($C$2:$C$150,F14,$D$2:$D$150) -> 0
G15: =SUMIF($C$2:$C$150,F15,$D$2:$D$150) -> 0
G16: =SUMIF($C$2:$C$150,F16,$D$2:$D$150) -> 0
G17: =SUMIF($C$2:$C$150,F17,$D$2:$D$150) -> 0
G18: =SUMIF($C$2:$C$150,F18,$D$2:$D$150) -> 0
G19: =SUMIF($C$2:$C$150,F19,$D$2:$D$150) -> 0
G20: =SUMIF($C$2:$C$150,F20,$D$2:$D$150) -> 0
G21: =SUMIF($C$2:$C$150,F21,$D$2:$D$150) -> 0
G22: =SUMIF($C$2:$C$150,F22,$D$2:$D$150) -> 0
G23: =SUMIF($C$2:$C$150,F23,$D$2:$D$150) -> 0
G24: =SUMIF($C$2:$C$150,F24,$D$2:$D$150) -> 0
G25: =SUMIF($C$2:$C$150,F25,$D$2:$D$150) -> 0
... G61: =SUMIF($C$2:$C$150,F61,$D$2:$D$150) -> 0

Sheet Aug 2026
A1: Date | B1: Asset Manager | C1: Company | D1: Value | F1: Summary | G1: Value | H1: Lists | M1: List | N1: Value
A2: 46235 | F2: {=_xlfn._xlws.SORT(_xlfn.UNIQUE(C2:C150))} -> 0 | G2: =SUMIF($C$2:$C$150,F2,$D$2:$D$150) -> 0 | M2: UN Blacklist 2023 | N2: =SUMIF($H$2:$H$150,"*UN Blacklist 2023*",$G$2:$G$150) -> 0
G3: =SUMIF($C$2:$C$150,F3,$D$2:$D$150) -> 0 | M3: UN Blacklist 2025 | N3: =SUMIF($H$2:$H$150,"*UN Blacklist 2025*",$G$2:$G$150) -> 0
G4: =SUMIF($C$2:$C$150,F4,$D$2:$D$150) -> 0 | M4: AFSC Divestment List 2025 | N4: =SUMIF($H$2:$H$97150,"*AFSC Divestment List 2025*",$G$2:$G$150) -> 0
G5: =SUMIF($C$2:$C$150,F5,$D$2:$D$150) -> 0 | M5: WhoProfits | N5: =SUMIF($H$2:$H$150,"*Who Profits*",$G$2:$G$150) -> 0
G6: =SUMIF($C$2:$C$150,F6,$D$2:$D$150) -> 0
G7: =SUMIF($C$2:$C$150,F7,$D$2:$D$150) -> 0 | M7: Bank | N7: Value
G8: =SUMIF($C$2:$C$150,F8,$D$2:$D$150) -> 0 | M8: Danske Bank | N8: =SUMIF($B$2:$B$150,"*Danske Bank*",$D$2:$D$150) -> 0
G9: =SUMIF($C$2:$C$150,F9,$D$2:$D$150) -> 0 | M9: Jyske Bank | N9: =SUMIF($B$2:$B$150,"*Jyske Bank*",$D$2:$D$150) -> 0
G10: =SUMIF($C$2:$C$150,F10,$D$2:$D$150) -> 0 | M10: SEB | N10: =SUMIF($B$2:$B$150,"*SEB*",$D$2:$D$150) -> 0
G11: =SUMIF($C$2:$C$150,F11,$D$2:$D$150) -> 0
G12: =SUMIF($C$2:$C$150,F12,$D$2:$D$150) -> 0 | M12: Total
G13: =SUMIF($C$2:$C$150,F13,$D$2:$D$150) -> 0 | M13: =SUM(D2:D150) -> 0
G14: =SUMIF($C$2:$C$150,F14,$D$2:$D$150) -> 0
G15: =SUMIF($C$2:$C$150,F15,$D$2:$D$150) -> 0
G16: =SUMIF($C$2:$C$150,F16,$D$2:$D$150) -> 0
G17: =SUMIF($C$2:$C$150,F17,$D$2:$D$150) -> 0
G18: =SUMIF($C$2:$C$150,F18,$D$2:$D$150) -> 0
G19: =SUMIF($C$2:$C$150,F19,$D$2:$D$150) -> 0
G20: =SUMIF($C$2:$C$150,F20,$D$2:$D$150) -> 0
G21: =SUMIF($C$2:$C$150,F21,$D$2:$D$150) -> 0
G22: =SUMIF($C$2:$C$150,F22,$D$2:$D$150) -> 0
G23: =SUMIF($C$2:$C$150,F23,$D$2:$D$150) -> 0
G24: =SUMIF($C$2:$C$150,F24,$D$2:$D$150) -> 0
G25: =SUMIF($C$2:$C$150,F25,$D$2:$D$150) -> 0
... G60: =SUMIF($C$2:$C$150,F60,$D$2:$D$150) -> 0

Sheet Sep 2026
A1: Date | B1: Asset Manager | C1: Company | D1: Value | F1: Summary | G1: Value | H1: Lists | M1: List | N1: Value
A2: 46266 | F2: {=_xlfn._xlws.SORT(_xlfn.UNIQUE(C2:C150))} -> 0 | G2: =SUMIF($C$2:$C$150,F2,$D$2:$D$150) -> 0 | M2: UN Blacklist 2023 | N2: =SUMIF($H$2:$H$150,"*UN Blacklist 2023*",$G$2:$G$150) -> 0
G3: =SUMIF($C$2:$C$150,F3,$D$2:$D$150) -> 0 | M3: UN Blacklist 2025 | N3: =SUMIF($H$2:$H$150,"*UN Blacklist 2025*",$G$2:$G$150) -> 0
G4: =SUMIF($C$2:$C$150,F4,$D$2:$D$150) -> 0 | M4: AFSC Divestment List 2025 | N4: =SUMIF($H$2:$H$97150,"*AFSC Divestment List 2025*",$G$2:$G$150) -> 0
G5: =SUMIF($C$2:$C$150,F5,$D$2:$D$150) -> 0 | M5: WhoProfits | N5: =SUMIF($H$2:$H$150,"*Who Profits*",$G$2:$G$150) -> 0
G6: =SUMIF($C$2:$C$150,F6,$D$2:$D$150) -> 0
G7: =SUMIF($C$2:$C$150,F7,$D$2:$D$150) -> 0 | M7: Bank | N7: Value
G8: =SUMIF($C$2:$C$150,F8,$D$2:$D$150) -> 0 | M8: Danske Bank | N8: =SUMIF($B$2:$B$150,"*Danske Bank*",$D$2:$D$150) -> 0
G9: =SUMIF($C$2:$C$150,F9,$D$2:$D$150) -> 0 | M9: Jyske Bank | N9: =SUMIF($B$2:$B$150,"*Jyske Bank*",$D$2:$D$150) -> 0
G10: =SUMIF($C$2:$C$150,F10,$D$2:$D$150) -> 0 | M10: SEB | N10: =SUMIF($B$2:$B$150,"*SEB*",$D$2:$D$150) -> 0
G11: =SUMIF($C$2:$C$150,F11,$D$2:$D$150) -> 0
G12: =SUMIF($C$2:$C$150,F12,$D$2:$D$150) -> 0 | M12: Total
G13: =SUMIF($C$2:$C$150,F13,$D$2:$D$150) -> 0 | M13: =SUM(D2:D150) -> 0
G14: =SUMIF($C$2:$C$150,F14,$D$2:$D$150) -> 0
G15: =SUMIF($C$2:$C$150,F15,$D$2:$D$150) -> 0
G16: =SUMIF($C$2:$C$150,F16,$D$2:$D$150) -> 0
G17: =SUMIF($C$2:$C$150,F17,$D$2:$D$150) -> 0
G18: =SUMIF($C$2:$C$150,F18,$D$2:$D$150) -> 0
G19: =SUMIF($C$2:$C$150,F19,$D$2:$D$150) -> 0
G20: =SUMIF($C$2:$C$150,F20,$D$2:$D$150) -> 0
G21: =SUMIF($C$2:$C$150,F21,$D$2:$D$150) -> 0
G22: =SUMIF($C$2:$C$150,F22,$D$2:$D$150) -> 0
G23: =SUMIF($C$2:$C$150,F23,$D$2:$D$150) -> 0
G24: =SUMIF($C$2:$C$150,F24,$D$2:$D$150) -> 0
G25: =SUMIF($C$2:$C$150,F25,$D$2:$D$150) -> 0
... G59: =SUMIF($C$2:$C$150,F59,$D$2:$D$150) -> 0

Sheet Oct 2026
A1: Date | B1: Asset Manager | C1: Company | D1: Value | F1: Summary | G1: Value | H1: Lists | M1: List | N1: Value
A2: 46296 | F2: {=_xlfn._xlws.SORT(_xlfn.UNIQUE(C2:C150))} -> 0 | G2: =SUMIF($C$2:$C$150,F2,$D$2:$D$150) -> 0 | M2: UN Blacklist 2023 | N2: =SUMIF($H$2:$H$150,"*UN Blacklist 2023*",$G$2:$G$150) -> 0
G3: =SUMIF($C$2:$C$150,F3,$D$2:$D$150) -> 0 | M3: UN Blacklist 2025 | N3: =SUMIF($H$2:$H$150,"*UN Blacklist 2025*",$G$2:$G$150) -> 0
G4: =SUMIF($C$2:$C$150,F4,$D$2:$D$150) -> 0 | M4: AFSC Divestment List 2025 | N4: =SUMIF($H$2:$H$97150,"*AFSC Divestment List 2025*",$G$2:$G$150) -> 0
G5: =SUMIF($C$2:$C$150,F5,$D$2:$D$150) -> 0 | M5: WhoProfits | N5: =SUMIF($H$2:$H$150,"*Who Profits*",$G$2:$G$150) -> 0
G6: =SUMIF($C$2:$C$150,F6,$D$2:$D$150) -> 0
G7: =SUMIF($C$2:$C$150,F7,$D$2:$D$150) -> 0 | M7: Bank | N7: Value
G8: =SUMIF($C$2:$C$150,F8,$D$2:$D$150) -> 0 | M8: Danske Bank | N8: =SUMIF($B$2:$B$150,"*Danske Bank*",$D$2:$D$150) -> 0
G9: =SUMIF($C$2:$C$150,F9,$D$2:$D$150) -> 0 | M9: Jyske Bank | N9: =SUMIF($B$2:$B$150,"*Jyske Bank*",$D$2:$D$150) -> 0
G10: =SUMIF($C$2:$C$150,F10,$D$2:$D$150) -> 0 | M10: SEB | N10: =SUMIF($B$2:$B$150,"*SEB*",$D$2:$D$150) -> 0
G11: =SUMIF($C$2:$C$150,F11,$D$2:$D$150) -> 0
G12: =SUMIF($C$2:$C$150,F12,$D$2:$D$150) -> 0 | M12: Total
G13: =SUMIF($C$2:$C$150,F13,$D$2:$D$150) -> 0 | M13: =SUM(D2:D150) -> 0
G14: =SUMIF($C$2:$C$150,F14,$D$2:$D$150) -> 0
G15: =SUMIF($C$2:$C$150,F15,$D$2:$D$150) -> 0
G16: =SUMIF($C$2:$C$150,F16,$D$2:$D$150) -> 0
G17: =SUMIF($C$2:$C$150,F17,$D$2:$D$150) -> 0
G18: =SUMIF($C$2:$C$150,F18,$D$2:$D$150) -> 0
G19: =SUMIF($C$2:$C$150,F19,$D$2:$D$150) -> 0
G20: =SUMIF($C$2:$C$150,F20,$D$2:$D$150) -> 0
G21: =SUMIF($C$2:$C$150,F21,$D$2:$D$150) -> 0
G22: =SUMIF($C$2:$C$150,F22,$D$2:$D$150) -> 0
G23: =SUMIF($C$2:$C$150,F23,$D$2:$D$150) -> 0
G24: =SUMIF($C$2:$C$150,F24,$D$2:$D$150) -> 0
G25: =SUMIF($C$2:$C$150,F25,$D$2:$D$150) -> 0
... G58: =SUMIF($C$2:$C$150,F58,$D$2:$D$150) -> 0

Sheet Nov 2026
A1: Date | B1: Asset Manager | C1: Company | D1: Value | F1: Summary | G1: Value | H1: Lists | M1: List | N1: Value
A2: 46327 | F2: {=_xlfn._xlws.SORT(_xlfn.UNIQUE(C2:C150))} -> 0 | G2: =SUMIF($C$2:$C$150,F2,$D$2:$D$150) -> 0 | M2: UN Blacklist 2023 | N2: =SUMIF($H$2:$H$150,"*UN Blacklist 2023*",$G$2:$G$150) -> 0
G3: =SUMIF($C$2:$C$150,F3,$D$2:$D$150) -> 0 | M3: UN Blacklist 2025 | N3: =SUMIF($H$2:$H$150,"*UN Blacklist 2025*",$G$2:$G$150) -> 0
G4: =SUMIF($C$2:$C$150,F4,$D$2:$D$150) -> 0 | M4: AFSC Divestment List 2025 | N4: =SUMIF($H$2:$H$97150,"*AFSC Divestment List 2025*",$G$2:$G$150) -> 0
G5: =SUMIF($C$2:$C$150,F5,$D$2:$D$150) -> 0 | M5: WhoProfits | N5: =SUMIF($H$2:$H$150,"*Who Profits*",$G$2:$G$150) -> 0
G6: =SUMIF($C$2:$C$150,F6,$D$2:$D$150) -> 0
G7: =SUMIF($C$2:$C$150,F7,$D$2:$D$150) -> 0 | M7: Bank | N7: Value
G8: =SUMIF($C$2:$C$150,F8,$D$2:$D$150) -> 0 | M8: Danske Bank | N8: =SUMIF($B$2:$B$150,"*Danske Bank*",$D$2:$D$150) -> 0
G9: =SUMIF($C$2:$C$150,F9,$D$2:$D$150) -> 0 | M9: Jyske Bank | N9: =SUMIF($B$2:$B$150,"*Jyske Bank*",$D$2:$D$150) -> 0
G10: =SUMIF($C$2:$C$150,F10,$D$2:$D$150) -> 0 | M10: SEB | N10: =SUMIF($B$2:$B$150,"*SEB*",$D$2:$D$150) -> 0
G11: =SUMIF($C$2:$C$150,F11,$D$2:$D$150) -> 0
G12: =SUMIF($C$2:$C$150,F12,$D$2:$D$150) -> 0 | M12: Total
G13: =SUMIF($C$2:$C$150,F13,$D$2:$D$150) -> 0 | M13: =SUM(D2:D150) -> 0
G14: =SUMIF($C$2:$C$150,F14,$D$2:$D$150) -> 0
G15: =SUMIF($C$2:$C$150,F15,$D$2:$D$150) -> 0
G16: =SUMIF($C$2:$C$150,F16,$D$2:$D$150) -> 0
G17: =SUMIF($C$2:$C$150,F17,$D$2:$D$150) -> 0
G18: =SUMIF($C$2:$C$150,F18,$D$2:$D$150) -> 0
G19: =SUMIF($C$2:$C$150,F19,$D$2:$D$150) -> 0
G20: =SUMIF($C$2:$C$150,F20,$D$2:$D$150) -> 0
G21: =SUMIF($C$2:$C$150,F21,$D$2:$D$150) -> 0
G22: =SUMIF($C$2:$C$150,F22,$D$2:$D$150) -> 0
G23: =SUMIF($C$2:$C$150,F23,$D$2:$D$150) -> 0
G24: =SUMIF($C$2:$C$150,F24,$D$2:$D$150) -> 0
G25: =SUMIF($C$2:$C$150,F25,$D$2:$D$150) -> 0
... G34: =SUMIF($C$2:$C$150,F34,$D$2:$D$150) -> 0
E35: AFSC Divestment List 2025 | G35: =SUMIF($C$2:$C$150,F35,$D$2:$D$150) -> 0
G36: =SUMIF($C$2:$C$150,F36,$D$2:$D$150) -> 0
G37: =SUMIF($C$2:$C$150,F37,$D$2:$D$150) -> 0
G38: =SUMIF($C$2:$C$150,F38,$D$2:$D$150) -> 0
G39: =SUMIF($C$2:$C$150,F39,$D$2:$D$150) -> 0
G40: =SUMIF($C$2:$C$150,F40,$D$2:$D$150) -> 0
G41: =SUMIF($C$2:$C$150,F41,$D$2:$D$150) -> 0
G42: =SUMIF($C$2:$C$150,F42,$D$2:$D$150) -> 0
G43: =SUMIF($C$2:$C$150,F43,$D$2:$D$150) -> 0
G44: =SUMIF($C$2:$C$150,F44,$D$2:$D$150) -> 0
G45: =SUMIF($C$2:$C$150,F45,$D$2:$D$150) -> 0
G46: =SUMIF($C$2:$C$150,F46,$D$2:$D$150) -> 0
G47: =SUMIF($C$2:$C$150,F47,$D$2:$D$150) -> 0
... G59: =SUMIF($C$2:$C$150,F59,$D$2:$D$150) -> 0

Sheet Dec 2026
A1: Date | B1: Asset Manager | C1: Company | D1: Value | F1: Summary | G1: Value | H1: Lists | M1: List | N1: Value
A2: 46357 | F2: {=_xlfn._xlws.SORT(_xlfn.UNIQUE(C2:C144))} -> 0 | G2: =SUMIF($C$2:$C$144,F2,$D$2:$D$144) -> 0 | M2: UN Blacklist 2023 | N2: =SUMIF($H$2:$H$144,"*UN Blacklist 2023*",$G$2:$G$144) -> 0
G3: =SUMIF($C$2:$C$144,F3,$D$2:$D$144) -> 0 | M3: UN Blacklist 2025 | N3: =SUMIF($H$2:$H$144,"*UN Blacklist 2025*",$G$2:$G$144) -> 0
G4: =SUMIF($C$2:$C$144,F4,$D$2:$D$144) -> 0 | M4: AFSC Divestment List 2025 | N4: =SUMIF($H$2:$H$97144,"*AFSC Divestment List 2025*",$G$2:$G$144) -> 0
G5: =SUMIF($C$2:$C$144,F5,$D$2:$D$144) -> 0 | M5: WhoProfits | N5: =SUMIF($H$2:$H$144,"*Who Profits*",$G$2:$G$144) -> 0
G6: =SUMIF($C$2:$C$144,F6,$D$2:$D$144) -> 0
G7: =SUMIF($C$2:$C$144,F7,$D$2:$D$144) -> 0 | M7: Bank | N7: Value
G8: =SUMIF($C$2:$C$144,F8,$D$2:$D$144) -> 0 | M8: Danske Bank | N8: =SUMIF($B$2:$B$144,"*Danske Bank*",$D$2:$D$144) -> 0
G9: =SUMIF($C$2:$C$144,F9,$D$2:$D$144) -> 0 | M9: Jyske Bank | N9: =SUMIF($B$2:$B$144,"*Jyske Bank*",$D$2:$D$144) -> 0
G10: =SUMIF($C$2:$C$144,F10,$D$2:$D$144) -> 0 | M10: SEB | N10: =SUMIF($B$2:$B$144,"*SEB*",$D$2:$D$144) -> 0
G11: =SUMIF($C$2:$C$144,F11,$D$2:$D$144) -> 0
G12: =SUMIF($C$2:$C$144,F12,$D$2:$D$144) -> 0 | M12: Total
G13: =SUMIF($C$2:$C$144,F13,$D$2:$D$144) -> 0 | M13: =SUM(D2:D144) -> 0
G14: =SUMIF($C$2:$C$144,F14,$D$2:$D$144) -> 0
G15: =SUMIF($C$2:$C$144,F15,$D$2:$D$144) -> 0
G16: =SUMIF($C$2:$C$144,F16,$D$2:$D$144) -> 0
G17: =SUMIF($C$2:$C$144,F17,$D$2:$D$144) -> 0
G18: =SUMIF($C$2:$C$144,F18,$D$2:$D$144) -> 0
G19: =SUMIF($C$2:$C$144,F19,$D$2:$D$144) -> 0
G20: =SUMIF($C$2:$C$144,F20,$D$2:$D$144) -> 0
G21: =SUMIF($C$2:$C$144,F21,$D$2:$D$144) -> 0
G22: =SUMIF($C$2:$C$144,F22,$D$2:$D$144) -> 0
G23: =SUMIF($C$2:$C$144,F23,$D$2:$D$144) -> 0
G24: =SUMIF($C$2:$C$144,F24,$D$2:$D$144) -> 0
G25: =SUMIF($C$2:$C$144,F25,$D$2:$D$144) -> 0
... G59: =SUMIF($C$2:$C$144,F59,$D$2:$D$144) -> 0
